{
 "cells": [
  {
   "cell_type": "code",
   "execution_count": 1,
   "metadata": {},
   "outputs": [
    {
     "name": "stdout",
     "output_type": "stream",
     "text": [
      "[name: \"/device:CPU:0\"\n",
      "device_type: \"CPU\"\n",
      "memory_limit: 268435456\n",
      "locality {\n",
      "}\n",
      "incarnation: 5900941511978133589\n",
      ", name: \"/device:GPU:0\"\n",
      "device_type: \"GPU\"\n",
      "memory_limit: 6562258206\n",
      "locality {\n",
      "  bus_id: 1\n",
      "  links {\n",
      "  }\n",
      "}\n",
      "incarnation: 18353043572148331820\n",
      "physical_device_desc: \"device: 0, name: GeForce GTX 1080, pci bus id: 0000:01:00.0, compute capability: 6.1\"\n",
      "]\n"
     ]
    }
   ],
   "source": [
    "from tensorflow.python.client import device_lib \n",
    "print(device_lib.list_local_devices())"
   ]
  },
  {
   "cell_type": "code",
   "execution_count": 2,
   "metadata": {},
   "outputs": [],
   "source": [
    "# importing the tensorflow package\n",
    "import tensorflow as tf "
   ]
  },
  {
   "cell_type": "code",
   "execution_count": 3,
   "metadata": {},
   "outputs": [
    {
     "data": {
      "text/plain": [
       "True"
      ]
     },
     "execution_count": 3,
     "metadata": {},
     "output_type": "execute_result"
    }
   ],
   "source": [
    "tf.test.is_built_with_cuda()"
   ]
  },
  {
   "cell_type": "code",
   "execution_count": 4,
   "metadata": {},
   "outputs": [
    {
     "data": {
      "text/plain": [
       "True"
      ]
     },
     "execution_count": 4,
     "metadata": {},
     "output_type": "execute_result"
    }
   ],
   "source": [
    "tf.test.is_gpu_available(cuda_only=False, min_cuda_compute_capability=None)"
   ]
  },
  {
   "cell_type": "code",
   "execution_count": 5,
   "metadata": {},
   "outputs": [
    {
     "ename": "AttributeError",
     "evalue": "module 'tensorflow' has no attribute 'Session'",
     "output_type": "error",
     "traceback": [
      "\u001b[1;31m---------------------------------------------------------------------------\u001b[0m",
      "\u001b[1;31mAttributeError\u001b[0m                            Traceback (most recent call last)",
      "\u001b[1;32m<ipython-input-5-dad9f5fa93d0>\u001b[0m in \u001b[0;36m<module>\u001b[1;34m\u001b[0m\n\u001b[1;32m----> 1\u001b[1;33m \u001b[0msess\u001b[0m \u001b[1;33m=\u001b[0m \u001b[0mtf\u001b[0m\u001b[1;33m.\u001b[0m\u001b[0mSession\u001b[0m\u001b[1;33m(\u001b[0m\u001b[0mconfig\u001b[0m\u001b[1;33m=\u001b[0m\u001b[0mtf\u001b[0m\u001b[1;33m.\u001b[0m\u001b[0mConfigProto\u001b[0m\u001b[1;33m(\u001b[0m\u001b[0mlog_device_placement\u001b[0m\u001b[1;33m=\u001b[0m\u001b[1;32mTrue\u001b[0m\u001b[1;33m)\u001b[0m\u001b[1;33m)\u001b[0m\u001b[1;33m\u001b[0m\u001b[1;33m\u001b[0m\u001b[0m\n\u001b[0m",
      "\u001b[1;31mAttributeError\u001b[0m: module 'tensorflow' has no attribute 'Session'"
     ]
    }
   ],
   "source": [
    "sess = tf.Session(config=tf.ConfigProto(log_device_placement=True))"
   ]
  },
  {
   "cell_type": "code",
   "execution_count": 6,
   "metadata": {},
   "outputs": [],
   "source": [
    "import tensorflow as tf"
   ]
  },
  {
   "cell_type": "code",
   "execution_count": 11,
   "metadata": {},
   "outputs": [
    {
     "name": "stderr",
     "output_type": "stream",
     "text": [
      "ERROR:root:Internal Python error in the inspect module.\n",
      "Below is the traceback from this internal error.\n",
      "\n"
     ]
    },
    {
     "name": "stdout",
     "output_type": "stream",
     "text": [
      "Traceback (most recent call last):\n",
      "  File \"c:\\users\\raph\\anaconda3\\envs\\mytfenv\\lib\\site-packages\\IPython\\core\\interactiveshell.py\", line 3331, in run_code\n",
      "    exec(code_obj, self.user_global_ns, self.user_ns)\n",
      "  File \"<ipython-input-11-65996cac02ec>\", line 1, in <module>\n",
      "    tf.__version__\n",
      "AttributeError: module 'tensorflow' has no attribute '__version__'\n",
      "\n",
      "During handling of the above exception, another exception occurred:\n",
      "\n",
      "Traceback (most recent call last):\n",
      "  File \"c:\\users\\raph\\anaconda3\\envs\\mytfenv\\lib\\site-packages\\IPython\\core\\interactiveshell.py\", line 2044, in showtraceback\n",
      "    stb = value._render_traceback_()\n",
      "AttributeError: 'AttributeError' object has no attribute '_render_traceback_'\n",
      "\n",
      "During handling of the above exception, another exception occurred:\n",
      "\n",
      "Traceback (most recent call last):\n",
      "  File \"c:\\users\\raph\\anaconda3\\envs\\mytfenv\\lib\\site-packages\\tensorflow_core\\python\\pywrap_tensorflow.py\", line 58, in <module>\n",
      "    from tensorflow.python.pywrap_tensorflow_internal import *\n",
      "  File \"c:\\users\\raph\\anaconda3\\envs\\mytfenv\\lib\\site-packages\\tensorflow_core\\python\\pywrap_tensorflow_internal.py\", line 28, in <module>\n",
      "    _pywrap_tensorflow_internal = swig_import_helper()\n",
      "  File \"c:\\users\\raph\\anaconda3\\envs\\mytfenv\\lib\\site-packages\\tensorflow_core\\python\\pywrap_tensorflow_internal.py\", line 24, in swig_import_helper\n",
      "    _mod = imp.load_module('_pywrap_tensorflow_internal', fp, pathname, description)\n",
      "  File \"c:\\users\\raph\\anaconda3\\envs\\mytfenv\\lib\\imp.py\", line 242, in load_module\n",
      "    return load_dynamic(name, filename, file)\n",
      "  File \"c:\\users\\raph\\anaconda3\\envs\\mytfenv\\lib\\imp.py\", line 342, in load_dynamic\n",
      "    return _load(spec)\n",
      "ImportError: DLL load failed: The specified module could not be found.\n",
      "\n",
      "During handling of the above exception, another exception occurred:\n",
      "\n",
      "Traceback (most recent call last):\n",
      "  File \"c:\\users\\raph\\anaconda3\\envs\\mytfenv\\lib\\site-packages\\IPython\\core\\ultratb.py\", line 1148, in get_records\n",
      "    return _fixed_getinnerframes(etb, number_of_lines_of_context, tb_offset)\n",
      "  File \"c:\\users\\raph\\anaconda3\\envs\\mytfenv\\lib\\site-packages\\IPython\\core\\ultratb.py\", line 316, in wrapped\n",
      "    return f(*args, **kwargs)\n",
      "  File \"c:\\users\\raph\\anaconda3\\envs\\mytfenv\\lib\\site-packages\\IPython\\core\\ultratb.py\", line 350, in _fixed_getinnerframes\n",
      "    records = fix_frame_records_filenames(inspect.getinnerframes(etb, context))\n",
      "  File \"c:\\users\\raph\\anaconda3\\envs\\mytfenv\\lib\\inspect.py\", line 1502, in getinnerframes\n",
      "    frameinfo = (tb.tb_frame,) + getframeinfo(tb, context)\n",
      "  File \"c:\\users\\raph\\anaconda3\\envs\\mytfenv\\lib\\inspect.py\", line 1460, in getframeinfo\n",
      "    filename = getsourcefile(frame) or getfile(frame)\n",
      "  File \"c:\\users\\raph\\anaconda3\\envs\\mytfenv\\lib\\inspect.py\", line 696, in getsourcefile\n",
      "    if getattr(getmodule(object, filename), '__loader__', None) is not None:\n",
      "  File \"c:\\users\\raph\\anaconda3\\envs\\mytfenv\\lib\\inspect.py\", line 733, in getmodule\n",
      "    if ismodule(module) and hasattr(module, '__file__'):\n",
      "  File \"c:\\users\\raph\\anaconda3\\envs\\mytfenv\\lib\\site-packages\\tensorflow\\__init__.py\", line 50, in __getattr__\n",
      "    module = self._load()\n",
      "  File \"c:\\users\\raph\\anaconda3\\envs\\mytfenv\\lib\\site-packages\\tensorflow\\__init__.py\", line 44, in _load\n",
      "    module = _importlib.import_module(self.__name__)\n",
      "  File \"c:\\users\\raph\\anaconda3\\envs\\mytfenv\\lib\\importlib\\__init__.py\", line 127, in import_module\n",
      "    return _bootstrap._gcd_import(name[level:], package, level)\n",
      "  File \"<frozen importlib._bootstrap>\", line 1006, in _gcd_import\n",
      "  File \"<frozen importlib._bootstrap>\", line 983, in _find_and_load\n",
      "  File \"<frozen importlib._bootstrap>\", line 953, in _find_and_load_unlocked\n",
      "  File \"<frozen importlib._bootstrap>\", line 219, in _call_with_frames_removed\n",
      "  File \"<frozen importlib._bootstrap>\", line 1006, in _gcd_import\n",
      "  File \"<frozen importlib._bootstrap>\", line 983, in _find_and_load\n",
      "  File \"<frozen importlib._bootstrap>\", line 967, in _find_and_load_unlocked\n",
      "  File \"<frozen importlib._bootstrap>\", line 677, in _load_unlocked\n",
      "  File \"<frozen importlib._bootstrap_external>\", line 728, in exec_module\n",
      "  File \"<frozen importlib._bootstrap>\", line 219, in _call_with_frames_removed\n",
      "  File \"c:\\users\\raph\\anaconda3\\envs\\mytfenv\\lib\\site-packages\\tensorflow_core\\__init__.py\", line 42, in <module>\n",
      "    from . _api.v2 import audio\n",
      "  File \"c:\\users\\raph\\anaconda3\\envs\\mytfenv\\lib\\site-packages\\tensorflow_core\\_api\\v2\\audio\\__init__.py\", line 10, in <module>\n",
      "    from tensorflow.python.ops.gen_audio_ops import decode_wav\n",
      "  File \"c:\\users\\raph\\anaconda3\\envs\\mytfenv\\lib\\site-packages\\tensorflow_core\\python\\ops\\gen_audio_ops.py\", line 9, in <module>\n",
      "    from tensorflow.python import pywrap_tensorflow as _pywrap_tensorflow\n",
      "  File \"c:\\users\\raph\\anaconda3\\envs\\mytfenv\\lib\\site-packages\\tensorflow\\__init__.py\", line 50, in __getattr__\n",
      "    module = self._load()\n",
      "  File \"c:\\users\\raph\\anaconda3\\envs\\mytfenv\\lib\\site-packages\\tensorflow\\__init__.py\", line 44, in _load\n",
      "    module = _importlib.import_module(self.__name__)\n",
      "  File \"c:\\users\\raph\\anaconda3\\envs\\mytfenv\\lib\\importlib\\__init__.py\", line 127, in import_module\n",
      "    return _bootstrap._gcd_import(name[level:], package, level)\n",
      "  File \"c:\\users\\raph\\anaconda3\\envs\\mytfenv\\lib\\site-packages\\tensorflow_core\\python\\__init__.py\", line 49, in <module>\n",
      "    from tensorflow.python import pywrap_tensorflow\n",
      "  File \"c:\\users\\raph\\anaconda3\\envs\\mytfenv\\lib\\site-packages\\tensorflow_core\\python\\pywrap_tensorflow.py\", line 74, in <module>\n",
      "    raise ImportError(msg)\n",
      "ImportError: Traceback (most recent call last):\n",
      "  File \"c:\\users\\raph\\anaconda3\\envs\\mytfenv\\lib\\site-packages\\IPython\\core\\interactiveshell.py\", line 3331, in run_code\n",
      "    exec(code_obj, self.user_global_ns, self.user_ns)\n",
      "  File \"<ipython-input-11-65996cac02ec>\", line 1, in <module>\n",
      "    tf.__version__\n",
      "AttributeError: module 'tensorflow' has no attribute '__version__'\n",
      "\n",
      "During handling of the above exception, another exception occurred:\n",
      "\n",
      "Traceback (most recent call last):\n",
      "  File \"c:\\users\\raph\\anaconda3\\envs\\mytfenv\\lib\\site-packages\\IPython\\core\\interactiveshell.py\", line 2044, in showtraceback\n",
      "    stb = value._render_traceback_()\n",
      "AttributeError: 'AttributeError' object has no attribute '_render_traceback_'\n",
      "\n",
      "During handling of the above exception, another exception occurred:\n",
      "\n",
      "Traceback (most recent call last):\n",
      "  File \"c:\\users\\raph\\anaconda3\\envs\\mytfenv\\lib\\site-packages\\tensorflow_core\\python\\pywrap_tensorflow.py\", line 58, in <module>\n",
      "    from tensorflow.python.pywrap_tensorflow_internal import *\n",
      "  File \"c:\\users\\raph\\anaconda3\\envs\\mytfenv\\lib\\site-packages\\tensorflow_core\\python\\pywrap_tensorflow_internal.py\", line 28, in <module>\n",
      "    _pywrap_tensorflow_internal = swig_import_helper()\n",
      "  File \"c:\\users\\raph\\anaconda3\\envs\\mytfenv\\lib\\site-packages\\tensorflow_core\\python\\pywrap_tensorflow_internal.py\", line 24, in swig_import_helper\n",
      "    _mod = imp.load_module('_pywrap_tensorflow_internal', fp, pathname, description)\n",
      "  File \"c:\\users\\raph\\anaconda3\\envs\\mytfenv\\lib\\imp.py\", line 242, in load_module\n",
      "    return load_dynamic(name, filename, file)\n",
      "  File \"c:\\users\\raph\\anaconda3\\envs\\mytfenv\\lib\\imp.py\", line 342, in load_dynamic\n",
      "    return _load(spec)\n",
      "ImportError: DLL load failed: The specified module could not be found.\n",
      "\n",
      "\n",
      "Failed to load the native TensorFlow runtime.\n",
      "\n",
      "See https://www.tensorflow.org/install/errors\n",
      "\n",
      "for some common reasons and solutions.  Include the entire stack trace\n",
      "above this error message when asking for help.\n"
     ]
    },
    {
     "ename": "AttributeError",
     "evalue": "module 'tensorflow' has no attribute '__version__'",
     "output_type": "error",
     "traceback": [
      "\u001b[1;31m---------------------------------------------------------------------------\u001b[0m"
     ]
    }
   ],
   "source": [
    "from tensorflow import Se\n"
   ]
  },
  {
   "cell_type": "code",
   "execution_count": null,
   "metadata": {},
   "outputs": [],
   "source": []
  }
 ],
 "metadata": {
  "kernelspec": {
   "display_name": "Python 3",
   "language": "python",
   "name": "python3"
  },
  "language_info": {
   "codemirror_mode": {
    "name": "ipython",
    "version": 3
   },
   "file_extension": ".py",
   "mimetype": "text/x-python",
   "name": "python",
   "nbconvert_exporter": "python",
   "pygments_lexer": "ipython3",
   "version": "3.7.6"
  }
 },
 "nbformat": 4,
 "nbformat_minor": 4
}
